Workbook

Sheet Dashboard
B2: Dashboard de Ventas | TA04 – Grupo 09
B4: Base de datos de ventas 2020–2022 · 996 registros | P4: Filtrar por año: | S4: Todos
B6: VENTAS TOTALES | G6: N° DE VENTAS | L6: TICKET PROMEDIO | Q6: PAGO CON TARJETA
B7: =Cálculos!B4 -> 230490.18 | G7: =Cálculos!B5 -> 996 | L7: =Cálculos!B6 -> 231.41584 | Q7: =Cálculos!B7 -> 0.096121796
B9: ="Año: "&$S$4 -> Año: Todos | G9: ="Productos distintos: "&Cálculos!B8 -> Productos distintos: 95 | L9: ="Total / N° de ventas" -> Total / N° de ventas | Q9: ="Efectivo: "&TEXT(1-Cálculos!B7,"0.0%") -> Efectivo: 90.4%
B11: ="Sector líder: "&Cálculos!J28&" (S/ "&TEXT(Cálculos!K28,"#,##0")&")" -> Sector líder: ALMACÉN (S/ 77,974) | I11: ="Mes con más ventas: "&Cálculos!J29&" (S/ "&TEXT(Cálculos!K29,"#,##0")&")" -> Mes con más ventas: Dic (S/ 31,276) | P11: ="Producto líder: "&Cálculos!J30&" (S/ "&TEXT(Cálculos!K30,"#,##0")&")" -> Producto líder: PASTEL (S/ 14,683)
B62: Fuente: TA04_G09 Base de datos (hoja Datos). Los gráficos y KPI se recalculan al cambiar el año en la celda amarilla.

Sheet Datos
A1: Código | B1: Día | C1: Mes | D1: Año | E1: Hora de atención | F1: N° de factura | G1: Producto | H1: Descripción | I1: Marca | J1: Proveedor | K1: Cantidad | L1: Un. | M1: Sector | N1: Precio por unidad (S/) | O1: Total (S/) | P1: Forma de pago | Q1: Fecha | R1: Franja horaria
A2: 1001 | B2: 27 | C2: 8 | D2: 2020 | E2: 0.88019676 | F2: 2727 | G2: ALFAJOR | H2: RELLENO CON DULCE DE LECHE | I2: NEVARES | J2: COMPAÑÍA AMERICANA DE ALIMENTOS S.A. | K2: 36 | L2: GR | M2: ALMACÉN | N2: 3.56 | O2: 128.16 | P2: EFECTIVO | Q2: =DATE(D2,C2,B2) -> 44070 | R2: =IF(HOUR(E2)<6,"Madrugada (0-5 h)",IF(HOUR(E2)<12,"Mañana (6-11 h)",IF(HOUR(E2)<18,"Tarde (12-17 h)","Noche (18-23 h)"))) -> Noche (18-23 h)
A3: 1002 | B3: 7 | C3: 1 | D3: 2022 | E3: 0.62476852 | F3: 2425 | G3: YERBA MATE | H3: MANZANILLA | I3: PLAYADITO | J3: COOP AGR.LIEBIG | K3: 47 | L3: GR | M3: ALMACÉN | N3: 3.21 | O3: 150.87 | P3: EFECTIVO | Q3: =DATE(D3,C3,B3) -> 44568 | R3: =IF(HOUR(E3)<6,"Madrugada (0-5 h)",IF(HOUR(E3)<12,"Mañana (6-11 h)",IF(HOUR(E3)<18,"Tarde (12-17 h)","Noche (18-23 h)"))) -> Tarde (12-17 h)
A4: 1003 | B4: 11 | C4: 3 | D4: 2021 | E4: 0.49042824 | F4: 1948 | G4: ARROZ | H4: LARGO FINO 00000 | I4: NOBLE | J4: COOP VILLA ELIZA | K4: 24 | L4: KG | M4: ALMACÉN | N4: 12.36 | O4: 296.64 | P4: TARJETA | Q4: =DATE(D4,C4,B4) -> 44266 | R4: =IF(HOUR(E4)<6,"Madrugada (0-5 h)",IF(HOUR(E4)<12,"Mañana (6-11 h)",IF(HOUR(E4)<18,"Tarde (12-17 h)","Noche (18-23 h)"))) -> Mañana (6-11 h)
A5: 1004 | B5: 26 | C5: 8 | D5: 2021 | E5: 0.32383102 | F5: 2223 | G5: DULCE DE LECHE | H5: LECHE EVAPORADA | I5: SAN IGNACIO | J5: ESTABLECIMIENTO SAN IGNACIO S.A. | K5: 1 | L5: GR | M5: LÁCTEOS | N5: 10.03 | O5: 10.03 | P5: EFECTIVO | Q5: =DATE(D5,C5,B5) -> 44434 | R5: =IF(HOUR(E5)<6,"Madrugada (0-5 h)",IF(HOUR(E5)<12,"Mañana (6-11 h)",IF(HOUR(E5)<18,"Tarde (12-17 h)","Noche (18-23 h)"))) -> Mañana (6-11 h)
A6: 1005 | B6: 3 | C6: 12 | D6: 2021 | E6: 0.2637037 | F6: 1541 | G6: QUESO CREMA | H6: ENTERO LIGHT EN POTE | I6: BONLE | J6: ESTABLECIMIENTO LOS OLIVOS S.A. | K6: 6 | L6: GR | M6: LÁCTEOS | N6: 16.05 | O6: 96.3 | P6: EFECTIVO | Q6: =DATE(D6,C6,B6) -> 44533 | R6: =IF(HOUR(E6)<6,"Madrugada (0-5 h)",IF(HOUR(E6)<12,"Mañana (6-11 h)",IF(HOUR(E6)<18,"Tarde (12-17 h)","Noche (18-23 h)"))) -> Mañana (6-11 h)
A7: 1006 | B7: 22 | C7: 9 | D7: 2022 | E7: 0.68831019 | F7: 1040 | G7: QUESO | H7: LIGHT | I7: GLORIA | J7: ESTABLECIMIENTO SAN ISIDRO S.A. | K7: 3 | L7: GR | M7: LÁCTEOS | N7: 16.5 | O7: 49.5 | P7: EFECTIVO | Q7: =DATE(D7,C7,B7) -> 44826 | R7: =IF(HOUR(E7)<6,"Madrugada (0-5 h)",IF(HOUR(E7)<12,"Mañana (6-11 h)",IF(HOUR(E7)<18,"Tarde (12-17 h)","Noche (18-23 h)"))) -> Tarde (12-17 h)
A8: 1007 | B8: 11 | C8: 6 | D8: 2021 | E8: 0.058159722 | F8: 4010 | G8: VINO TINTO | H8: SYRAH BONARDA | I8: CRUZ DEL SUR | J8: FECOVITA | K8: 29 | L8: CC | M8: BEBIDAS | N8: 4.13 | O8: 119.77 | P8: TARJETA | Q8: =DATE(D8,C8,B8) -> 44358 | R8: =IF(HOUR(E8)<6,"Madrugada (0-5 h)",IF(HOUR(E8)<12,"Mañana (6-11 h)",IF(HOUR(E8)<18,"Tarde (12-17 h)","Noche (18-23 h)"))) -> Madrugada (0-5 h)
A9: 1008 | B9: 1 | C9: 11 | D9: 2021 | E9: 0.98795139 | F9: 2260 | G9: ALCOHOL ETÍLICO | H9: 96° | I9: M.F. | J9: FRADEALCO S.A | K9: 50 | L9: CC | M9: ALMACÉN | N9: 11.5 | O9: 575 | P9: EFECTIVO | Q9: =DATE(D9,C9,B9) -> 44501 | R9: =IF(HOUR(E9)<6,"Madrugada (0-5 h)",IF(HOUR(E9)<12,"Mañana (6-11 h)",IF(HOUR(E9)<18,"Tarde (12-17 h)","Noche (18-23 h)"))) -> Noche (18-23 h)
A10: 1009 | B10: 28 | C10: 6 | D10: 2022 | E10: 0.19387731 | F10: 3383 | G10: PAN DE MESA | H10: PAN DE MESA RF 380G LAC | I10: LACTAL | J10: GRUPO BIMBO | K10: 37 | L10: GR | M10: PANIFICADOS | N10: 5.5 | O10: 203.5 | P10: EFECTIVO | Q10: =DATE(D10,C10,B10) -> 44740 | R10: =IF(HOUR(E10)<6,"Madrugada (0-5 h)",IF(HOUR(E10)<12,"Mañana (6-11 h)",IF(HOUR(E10)<18,"Tarde (12-17 h)","Noche (18-23 h)"))) -> Madrugada (0-5 h)
A11: 1010 | B11: 23 | C11: 9 | D11: 2021 | E11: 0.011377315 | F11: 2932 | G11: DETERGENTE | H11: ULTRA LIMON | I11: VENCEDOR | J11: GRUPO QUERUCLOR | K11: 13 | L11: CC | M11: LIMPIEZA | N11: 13.71 | O11: 178.23 | P11: EFECTIVO | Q11: =DATE(D11,C11,B11) -> 44462 | R11: =IF(HOUR(E11)<6,"Madrugada (0-5 h)",IF(HOUR(E11)<12,"Mañana (6-11 h)",IF(HOUR(E11)<18,"Tarde (12-17 h)","Noche (18-23 h)"))) -> Madrugada (0-5 h)
A12: 1011 | B12: 5 | C12: 6 | D12: 2021 | E12: 0.091284722 | F12: 4924 | G12: ALGODÓN | H12: COMÚN | I12: ESTRELLA | J12: GRUPO VICENTIN ‐ ALGODONERA AVELLANEDA | K12: 32 | L12: UN | M12: PERFUMERÍA | N12: 7.89 | O12: 252.48 | P12: EFECTIVO | Q12: =DATE(D12,C12,B12) -> 44352 | R12: =IF(HOUR(E12)<6,"Madrugada (0-5 h)",IF(HOUR(E12)<12,"Mañana (6-11 h)",IF(HOUR(E12)<18,"Tarde (12-17 h)","Noche (18-23 h)"))) -> Madrugada (0-5 h)
A13: 1012 | B13: 15 | C13: 9 | D13: 2021 | E13: 0.73212963 | F13: 2036 | G13: SAL | H13: GRUESA PAQUETE | I13: CELUSAL | J13: INDUSTRIAS QUIMICAS Y MINERAS TIMBO S.A. | K13: 13 | L13: KG | M13: ALMACÉN | N13: 6 | O13: 78 | P13: TARJETA | Q13: =DATE(D13,C13,B13) -> 44454 | R13: =IF(HOUR(E13)<6,"Madrugada (0-5 h)",IF(HOUR(E13)<12,"Mañana (6-11 h)",IF(HOUR(E13)<18,"Tarde (12-17 h)","Noche (18-23 h)"))) -> Tarde (12-17 h)
... A997: 1996 | B997: 15 | C997: 4 | D997: 2022 | E997: 0.755 | F997: 2172 | G997: LAPICEROS | H997: DEFINE BONITO | I997: PAILONTS | J997: PINT S.A | K997: 25 | L997: CC | M997: ALMACÉN | N997: 2.03 | O997: 50.75 | P997: EFECTIVO | Q997: =DATE(D997,C997,B997) -> 44666 | R997: =IF(HOUR(E997)<6,"Madrugada (0-5 h)",IF(HOUR(E997)<12,"Mañana (6-11 h)",IF(HOUR(E997)<18,"Tarde (12-17 h)","Noche (18-23 h)"))) -> Noche (18-23 h)

Sheet Cálculos
A1: Cálculos de apoyo del dashboard (no editar: todo son fórmulas sobre la hoja Datos)
A2: Criterio de año | B2: =IF(Dashboard!$S$4="Todos",">0",Dashboard!$S$4*1) -> >0
A4: Ventas totales (S/) | B4: =SUMIFS(Datos!$O$2:$O$997,Datos!$D$2:$D$997,$B$2) -> 230490.18
A5: N° de ventas | B5: =COUNTIFS(Datos!$D$2:$D$997,$B$2) -> 996
A6: Ticket promedio (S/) | B6: =IFERROR(B4/B5,0) -> 231.41584
A7: % pagado con tarjeta | B7: =IFERROR(SUMIFS(Datos!$O$2:$O$997,Datos!$D$2:$D$997,$B$2,Datos!$P$2:$P$997,"TARJETA")/B4,0) -> 0.096121796
A8: Productos distintos vendidos | B8: =COUNTIF(B43:B137,">0") -> 95
A11: Mes | B11: Ventas (S/) | D11: Sector | E11: Ventas (S/) | G11: Forma de pago | H11: Ventas (S/) | J11: Franja horaria | K11: Ventas (S/) | M11: Año | N11: Ventas (S/)
A12: Ene | B12: =SUMIFS(Datos!$O$2:$O$997,Datos!$D$2:$D$997,$B$2,Datos!$C$2:$C$997,ROW()-11) -> 17409.73 | D12: ALMACÉN | E12: =SUMIFS(Datos!$O$2:$O$997,Datos!$D$2:$D$997,$B$2,Datos!$M$2:$M$997,D12) -> 77974.14 | G12: EFECTIVO | H12: =SUMIFS(Datos!$O$2:$O$997,Datos!$D$2:$D$997,$B$2,Datos!$P$2:$P$997,G12) -> 208335.05 | J12: Madrugada (0-5 h) | K12: =SUMIFS(Datos!$O$2:$O$997,Datos!$D$2:$D$997,$B$2,Datos!$R$2:$R$997,J12) -> 47932.11 | M12: 2020 | N12: =SUMIFS(Datos!$O$2:$O$997,Datos!$D$2:$D$997,M12) -> 352.44
A13: Feb | B13: =SUMIFS(Datos!$O$2:$O$997,Datos!$D$2:$D$997,$B$2,Datos!$C$2:$C$997,ROW()-11) -> 18746.64 | D13: LIMPIEZA | E13: =SUMIFS(Datos!$O$2:$O$997,Datos!$D$2:$D$997,$B$2,Datos!$M$2:$M$997,D13) -> 47316.66 | G13: TARJETA | H13: =SUMIFS(Datos!$O$2:$O$997,Datos!$D$2:$D$997,$B$2,Datos!$P$2:$P$997,G13) -> 22155.13 | J13: Mañana (6-11 h) | K13: =SUMIFS(Datos!$O$2:$O$997,Datos!$D$2:$D$997,$B$2,Datos!$R$2:$R$997,J13) -> 67213.14 | M13: 2021 | N13: =SUMIFS(Datos!$O$2:$O$997,Datos!$D$2:$D$997,M13) -> 111826.19
A14: Mar | B14: =SUMIFS(Datos!$O$2:$O$997,Datos!$D$2:$D$997,$B$2,Datos!$C$2:$C$997,ROW()-11) -> 17069.6 | D14: PERFUMERÍA | E14: =SUMIFS(Datos!$O$2:$O$997,Datos!$D$2:$D$997,$B$2,Datos!$M$2:$M$997,D14) -> 42533.4 | J14: Tarde (12-17 h) | K14: =SUMIFS(Datos!$O$2:$O$997,Datos!$D$2:$D$997,$B$2,Datos!$R$2:$R$997,J14) -> 48484.2 | M14: 2022 | N14: =SUMIFS(Datos!$O$2:$O$997,Datos!$D$2:$D$997,M14) -> 118311.55
A15: Abr | B15: =SUMIFS(Datos!$O$2:$O$997,Datos!$D$2:$D$997,$B$2,Datos!$C$2:$C$997,ROW()-11) -> 14869.14 | D15: FRESCO | E15: =SUMIFS(Datos!$O$2:$O$997,Datos!$D$2:$D$997,$B$2,Datos!$M$2:$M$997,D15) -> 33561.46 | J15: Noche (18-23 h) | K15: =SUMIFS(Datos!$O$2:$O$997,Datos!$D$2:$D$997,$B$2,Datos!$R$2:$R$997,J15) -> 66860.73
A16: May | B16: =SUMIFS(Datos!$O$2:$O$997,Datos!$D$2:$D$997,$B$2,Datos!$C$2:$C$997,ROW()-11) -> 18126.88 | D16: LÁCTEOS | E16: =SUMIFS(Datos!$O$2:$O$997,Datos!$D$2:$D$997,$B$2,Datos!$M$2:$M$997,D16) -> 20132.29
A17: Jun | B17: =SUMIFS(Datos!$O$2:$O$997,Datos!$D$2:$D$997,$B$2,Datos!$C$2:$C$997,ROW()-11) -> 16518.26 | D17: BEBIDAS | E17: =SUMIFS(Datos!$O$2:$O$997,Datos!$D$2:$D$997,$B$2,Datos!$M$2:$M$997,D17) -> 4659.97
A18: Jul | B18: =SUMIFS(Datos!$O$2:$O$997,Datos!$D$2:$D$997,$B$2,Datos!$C$2:$C$997,ROW()-11) -> 18755.77 | D18: CARNES Y PROCESADOS | E18: =SUMIFS(Datos!$O$2:$O$997,Datos!$D$2:$D$997,$B$2,Datos!$M$2:$M$997,D18) -> 1686.42
A19: Ago | B19: =SUMIFS(Datos!$O$2:$O$997,Datos!$D$2:$D$997,$B$2,Datos!$C$2:$C$997,ROW()-11) -> 17703.31 | D19: PANIFICADOS | E19: =SUMIFS(Datos!$O$2:$O$997,Datos!$D$2:$D$997,$B$2,Datos!$M$2:$M$997,D19) -> 1666.5
A20: Sep | B20: =SUMIFS(Datos!$O$2:$O$997,Datos!$D$2:$D$997,$B$2,Datos!$C$2:$C$997,ROW()-11) -> 21406.66 | D20: EMBUTIDOS | E20: =SUMIFS(Datos!$O$2:$O$997,Datos!$D$2:$D$997,$B$2,Datos!$M$2:$M$997,D20) -> 959.34
A21: Oct | B21: =SUMIFS(Datos!$O$2:$O$997,Datos!$D$2:$D$997,$B$2,Datos!$C$2:$C$997,ROW()-11) -> 17206.32
A22: Nov | B22: =SUMIFS(Datos!$O$2:$O$997,Datos!$D$2:$D$997,$B$2,Datos!$C$2:$C$997,ROW()-11) -> 21401.51
A23: Dic | B23: =SUMIFS(Datos!$O$2:$O$997,Datos!$D$2:$D$997,$B$2,Datos!$C$2:$C$997,ROW()-11) -> 31276.36
A27: N° | B27: Top 10 productos | C27: Ventas (S/) | E27: N° | F27: Top 5 proveedores | G27: Ventas (S/) | J27: Hallazgos
A28: 1 | B28: =INDEX($A$43:$A$137,MATCH(A28,$D$43:$D$137,0)) -> PASTEL | C28: =INDEX($B$43:$B$137,MATCH(A28,$D$43:$D$137,0)) -> 14683.04 | E28: 1 | F28: =INDEX($F$43:$F$135,MATCH(E28,$I$43:$I$135,0)) -> YUMMI | G28: =INDEX($G$43:$G$135,MATCH(E28,$I$43:$I$135,0)) -> 14683.04 | J28: =INDEX(D12:D20,MATCH(MAX(E12:E20),E12:E20,0)) -> ALMACÉN | K28: =MAX(E12:E20) -> 77974.14
A29: 2 | B29: =INDEX($A$43:$A$137,MATCH(A29,$D$43:$D$137,0)) -> TORTA | C29: =INDEX($B$43:$B$137,MATCH(A29,$D$43:$D$137,0)) -> 13824 | E29: 2 | F29: =INDEX($F$43:$F$135,MATCH(E29,$I$43:$I$135,0)) -> FOOD | G29: =INDEX($G$43:$G$135,MATCH(E29,$I$43:$I$135,0)) -> 13824 | J29: =INDEX(A12:A23,MATCH(MAX(B12:B23),B12:B23,0)) -> Dic | K29: =MAX(B12:B23) -> 31276.36
A30: 3 | B30: =INDEX($A$43:$A$137,MATCH(A30,$D$43:$D$137,0)) -> DETERGENTE | C30: =INDEX($B$43:$B$137,MATCH(A30,$D$43:$D$137,0)) -> 8404.23 | E30: 3 | F30: =INDEX($F$43:$F$135,MATCH(E30,$I$43:$I$135,0)) -> FADIAL SRL | G30: =INDEX($G$43:$G$135,MATCH(E30,$I$43:$I$135,0)) -> 11512.38 | J30: =B28 -> PASTEL | K30: =C28 -> 14683.04
A31: 4 | B31: =INDEX($A$43:$A$137,MATCH(A31,$D$43:$D$137,0)) -> LUSTRAMUEBLES | C31: =INDEX($B$43:$B$137,MATCH(A31,$D$43:$D$137,0)) -> 7032.45 | E31: 4 | F31: =INDEX($F$43:$F$135,MATCH(E31,$I$43:$I$135,0)) -> CERA SUIZA | G31: =INDEX($G$43:$G$135,MATCH(E31,$I$43:$I$135,0)) -> 7032.45
A32: 5 | B32: =INDEX($A$43:$A$137,MATCH(A32,$D$43:$D$137,0)) -> COLONIA | C32: =INDEX($B$43:$B$137,MATCH(A32,$D$43:$D$137,0)) -> 6693.35 | E32: 5 | F32: =INDEX($F$43:$F$135,MATCH(E32,$I$43:$I$135,0)) -> LABORATORIOS KITY | G32: =INDEX($G$43:$G$135,MATCH(E32,$I$43:$I$135,0)) -> 6693.35
A33: 6 | B33: =INDEX($A$43:$A$137,MATCH(A33,$D$43:$D$137,0)) -> SUAVIZANTE | C33: =INDEX($B$43:$B$137,MATCH(A33,$D$43:$D$137,0)) -> 6439.68
A34: 7 | B34: =INDEX($A$43:$A$137,MATCH(A34,$D$43:$D$137,0)) -> COLLAR | C34: =INDEX($B$43:$B$137,MATCH(A34,$D$43:$D$137,0)) -> 5614
A35: 8 | B35: =INDEX($A$43:$A$137,MATCH(A35,$D$43:$D$137,0)) -> SHAMPOO | C35: =INDEX($B$43:$B$137,MATCH(A35,$D$43:$D$137,0)) -> 5420.85
A36: 9 | B36: =INDEX($A$43:$A$137,MATCH(A36,$D$43:$D$137,0)) -> SHAMPOO BABY | C36: =INDEX($B$43:$B$137,MATCH(A36,$D$43:$D$137,0)) -> 5350.17
A37: 10 | B37: =INDEX($A$43:$A$137,MATCH(A37,$D$43:$D$137,0)) -> DETERGENTE LIQUIDO | C37: =INDEX($B$43:$B$137,MATCH(A37,$D$43:$D$137,0)) -> 4501.44
A42: Producto | B42: Ventas (S/) | C42: Auxiliar | D42: Ranking | F42: Proveedor | G42: Ventas (S/) | H42: Auxiliar | I42: Ranking
A43: ACEITE | B43: =SUMIFS(Datos!$O$2:$O$997,Datos!$G$2:$G$997,A43,Datos!$D$2:$D$997,$B$2) -> 2064.16 | C43: =B43+ROW()/1000000 -> 2064.16 | D43: =RANK(C43,$C$43:$C$137,0) -> 39 | F43: ALICORP ARGENTINA S.C.A. | G43: =SUMIFS(Datos!$O$2:$O$997,Datos!$J$2:$J$997,F43,Datos!$D$2:$D$997,$B$2) -> 2189.94 | H43: =G43+ROW()/1000000 -> 2189.94 | I43: =RANK(H43,$H$43:$H$135,0) -> 36
A44: ACONDICIONADOR | B44: =SUMIFS(Datos!$O$2:$O$997,Datos!$G$2:$G$997,A44,Datos!$D$2:$D$997,$B$2) -> 3158.75 | C44: =B44+ROW()/1000000 -> 3158.75 | D44: =RANK(C44,$C$43:$C$137,0) -> 22 | F44: ALIMENTOS PREM S.A. | G44: =SUMIFS(Datos!$O$2:$O$997,Datos!$J$2:$J$997,F44,Datos!$D$2:$D$997,$B$2) -> 1623.24 | H44: =G44+ROW()/1000000 -> 1623.24 | I44: =RANK(H44,$H$43:$H$135,0) -> 55
A45: AGUA MINERAL NATURAL | B45: =SUMIFS(Datos!$O$2:$O$997,Datos!$G$2:$G$997,A45,Datos!$D$2:$D$997,$B$2) -> 868 | C45: =B45+ROW()/1000000 -> 868.00005 | D45: =RANK(C45,$C$43:$C$137,0) -> 81 | F45: ALIMENTOS SALUS.A. | G45: =SUMIFS(Datos!$O$2:$O$997,Datos!$J$2:$J$997,F45,Datos!$D$2:$D$997,$B$2) -> 2180.85 | H45: =G45+ROW()/1000000 -> 2180.85 | I45: =RANK(H45,$H$43:$H$135,0) -> 37
A46: AGUA SABORIZADA | B46: =SUMIFS(Datos!$O$2:$O$997,Datos!$G$2:$G$997,A46,Datos!$D$2:$D$997,$B$2) -> 799.1 | C46: =B46+ROW()/1000000 -> 799.10005 | D46: =RANK(C46,$C$43:$C$137,0) -> 85 | F46: AMBROSOLI | G46: =SUMIFS(Datos!$O$2:$O$997,Datos!$J$2:$J$997,F46,Datos!$D$2:$D$997,$B$2) -> 97.5 | H46: =G46+ROW()/1000000 -> 97.500046 | I46: =RANK(H46,$H$43:$H$135,0) -> 93
A47: AJINOMOTO | B47: =SUMIFS(Datos!$O$2:$O$997,Datos!$G$2:$G$997,A47,Datos!$D$2:$D$997,$B$2) -> 522.6 | C47: =B47+ROW()/1000000 -> 522.60005 | D47: =RANK(C47,$C$43:$C$137,0) -> 90 | F47: ARCOR | G47: =SUMIFS(Datos!$O$2:$O$997,Datos!$J$2:$J$997,F47,Datos!$D$2:$D$997,$B$2) -> 455.7 | H47: =G47+ROW()/1000000 -> 455.70005 | I47: =RANK(H47,$H$43:$H$135,0) -> 89
A48: AJÍ MOLIDO | B48: =SUMIFS(Datos!$O$2:$O$997,Datos!$G$2:$G$997,A48,Datos!$D$2:$D$997,$B$2) -> 1438.15 | C48: =B48+ROW()/1000000 -> 1438.15 | D48: =RANK(C48,$C$43:$C$137,0) -> 59 | F48: BEELS | G48: =SUMIFS(Datos!$O$2:$O$997,Datos!$J$2:$J$997,F48,Datos!$D$2:$D$997,$B$2) -> 1940.12 | H48: =G48+ROW()/1000000 -> 1940.12 | I48: =RANK(H48,$H$43:$H$135,0) -> 48
A49: ALCOHOL | B49: =SUMIFS(Datos!$O$2:$O$997,Datos!$G$2:$G$997,A49,Datos!$D$2:$D$997,$B$2) -> 3282.5 | C49: =B49+ROW()/1000000 -> 3282.5 | D49: =RANK(C49,$C$43:$C$137,0) -> 19 | F49: BELLS S.A | G49: =SUMIFS(Datos!$O$2:$O$997,Datos!$J$2:$J$997,F49,Datos!$D$2:$D$997,$B$2) -> 2064.16 | H49: =G49+ROW()/1000000 -> 2064.16 | I49: =RANK(H49,$H$43:$H$135,0) -> 42
A50: ALCOHOL ETÍLICO | B50: =SUMIFS(Datos!$O$2:$O$997,Datos!$G$2:$G$997,A50,Datos!$D$2:$D$997,$B$2) -> 3657 | C50: =B50+ROW()/1000000 -> 3657.0001 | D50: =RANK(C50,$C$43:$C$137,0) -> 15 | F50: CAKE BOUTIQUE | G50: =SUMIFS(Datos!$O$2:$O$997,Datos!$J$2:$J$997,F50,Datos!$D$2:$D$997,$B$2) -> 5614 | H50: =G50+ROW()/1000000 -> 5614 | I50: =RANK(H50,$H$43:$H$135,0) -> 6
...

Sheet Notas
A1: Notas sobre los datos y la limpieza
A2: 1. Fuente: archivo TA04_G09_MascotasBase_de_datos.csv, 996 ventas (hoja Datos).
A3: 2. Los precios y totales venían como texto ("S/3.56"); se convirtieron a números. Todos los totales coinciden con cantidad × precio unitario.
A4: 3. "Limpieza" y "LIMPIEZA" se unificaron en un solo sector; se quitaron espacios sobrantes en producto, proveedor y forma de pago.
A5: 4. Nueve ventas no tenían unidad de medida; se marcaron como "S/D" (sin dato).
A6: 5. Solo hay 5 ventas de 2020; por eso 2021 y 2022 concentran casi todo el análisis.
A7: 6. Las unidades (GR, UN, CC, KG, ML, LT, KL) son distintas, por lo que no se suman cantidades; el análisis usa solo importes en soles.
A8: 7. Columnas Fecha y Franja horaria (hoja Datos) son fórmulas: franja = madrugada 0-5 h, mañana 6-11 h, tarde 12-17 h, noche 18-23 h.
A9: 8. La lista de productos y precios de las columnas T:U del CSV original no se incluyó: es un catálogo de referencia, no ventas.
